<?xml version="1.0" encoding="UTF-8"?>
<!-- Generated by org.testng.reporters.JUnitReportReporter -->
<testsuite hostname="WQ-20161118QVKS" name="com.jay.testcases.TestLogin" tests="4" failures="1" timestamp="24 Mar 2017 12:13:12 GMT" time="36.543" errors="0">
  <testcase name="loginFail" time="10.621" classname="com.jay.testcases.TestLogin"/>
  <testcase name="loginSuccess" time="8.070" classname="com.jay.testcases.TestLogin">
    <failure type="java.lang.AssertionError" message="查找元素异常，退出当前测试用例">
      <![CDATA[java.lang.AssertionError: 查找元素异常，退出当前测试用例
	at org.testng.Assert.fail(Assert.java:94)
	at com.jay.uiframework.WebElemntUtils.getElement(WebElemntUtils.java:60)
	at com.jay.uiframework.WebElemntUtils$1.apply(WebElemntUtils.java:69)
	at com.jay.uiframework.WebElemntUtils$1.apply(WebElemntUtils.java:1)
	at org.openqa.selenium.support.ui.FluentWait.until(FluentWait.java:238)
	at com.jay.uiframework.WebElemntUtils.findElement(WebElemntUtils.java:67)
	at com.jay.uiframework.WebElemntUtils.getText(WebElemntUtils.java:101)
	at com.jay.pages.MainPage.getLoginUsername(MainPage.java:22)
	at com.jay.actions.LoginOperate.loginSuccessGetUsername(LoginOperate.java:36)
	at com.jay.testcases.TestLogin.loginSuccess(TestLogin.java:21)
	at sun.reflect.NativeMethodAccessorImpl.invoke0(Native Method)
	at sun.reflect.NativeMethodAccessorImpl.invoke(NativeMethodAccessorImpl.java:62)
	at sun.reflect.DelegatingMethodAccessorImpl.invoke(DelegatingMethodAccessorImpl.java:43)
	at java.lang.reflect.Method.invoke(Method.java:497)
	at org.testng.internal.MethodInvocationHelper.invokeMethod(MethodInvocationHelper.java:86)
	at org.testng.internal.Invoker.invokeMethod(Invoker.java:643)
	at org.testng.internal.Invoker.invokeTestMethod(Invoker.java:820)
	at org.testng.internal.Invoker.invokeTestMethods(Invoker.java:1128)
	at org.testng.internal.TestMethodWorker.invokeTestMethods(TestMethodWorker.java:129)
	at org.testng.internal.TestMethodWorker.run(TestMethodWorker.java:112)
	at org.testng.TestRunner.privateRun(TestRunner.java:782)
	at org.testng.TestRunner.run(TestRunner.java:632)
	at org.testng.SuiteRunner.runTest(SuiteRunner.java:366)
	at org.testng.SuiteRunner.runSequentially(SuiteRunner.java:361)
	at org.testng.SuiteRunner.privateRun(SuiteRunner.java:319)
	at org.testng.SuiteRunner.run(SuiteRunner.java:268)
	at org.testng.SuiteRunnerWorker.runSuite(SuiteRunnerWorker.java:52)
	at org.testng.SuiteRunnerWorker.run(SuiteRunnerWorker.java:86)
	at org.testng.TestNG.runSuitesSequentially(TestNG.java:1244)
	at org.testng.TestNG.runSuitesLocally(TestNG.java:1169)
	at org.testng.TestNG.run(TestNG.java:1064)
	at org.testng.remote.RemoteTestNG.run(RemoteTestNG.java:113)
	at org.testng.remote.RemoteTestNG.initAndRun(RemoteTestNG.java:206)
	at org.testng.remote.RemoteTestNG.main(RemoteTestNG.java:177)
]]>
    </failure>
  </testcase> <!-- loginSuccess -->
  <testcase name="loginFail2" time="10.287" classname="com.jay.testcases.TestLogin"/>
  <testcase name="loginSuccess" time="7.565" classname="com.jay.testcases.TestLogin"/>
</testsuite> <!-- com.jay.testcases.TestLogin -->
